Workbook
Name Fullname: _xlfn.LAMBDA(_xlpm.Name1,_xlpm.Name2,_xlpm.Name1 & IF(_xlpm.Name2 = "", "", " " & _xlpm.Name2))

Sheet Kunde
A1: Kunden-Karteikarte
B3: Vertragspartner | C3: Rechnungsempfänger | E3: Ansprechpartner
A4: Name | B4: Friedrich von Lien AG | D4: Anrede | E4: Herr | F4: Abteilung
D5: Nachname | E5: von Rönn | F5: Buchhaltung
A6: Strasse | B6: Moordamm 4 | D6: Vorname | E6: Luca
A7: PLZ, Ort | B7: 27404 Zeven | D7: Titel/Abteilung
A8: Telefon | D8: Telefon | E8: 04281 - 9515112
A9: E-Mail | D9: Mobil
D10: E-Mail | E10: luca.von-roenn@von-lien.de | F10: buchhaltung@von-lien.de
B11: Bankverbindung | C11: Gutschriften | D11: Ausweis-Nr.
A12: IBAN | B12: DE58 2926 5747 7436 7315 00 | D12: Geburtsdatum
A13: Bank | B13: Volksbank im Elbe-Weser-Dreieck | D13: Haupt-Asp | E13: TRUE | F13: FALSE | G13: FALSE | H13: FALSE
A14: BIC | B14: GENODEF1BEV | D14: Notizen
B16: Handelsregister | C16: Gewerbeschein | E16: Notizen
A17: Nummer | B17: HRB 121343 | E17: VVL-fähige in TM327 überführen im Zuge der VVL: BMMH3, CF1+, 1x MultiSIM Hardware immer +50,00 € (nur zukünftigtige VVL)
A18: Ort | B18: Tostedt
B20: Sonstiges
A21: Kundennummer
A22: Rechnung vom | B22: 43850
A23: Analyse vom | B23: 43861
A24: Kunde seit | B24: 43910
A25: Kartenanzahl | B25: 90
A26: Vertriebler | B26: Lehrmann
A27: Kennwort | B27: WECKMAN1
A28: Zahlungsart | B28: Überweisung
C30: Dies ist nur ein Test, die Daten stammen von der Karteikarte von Friedrich von Lien
B32: Vorteile | E32: Vorteile der nächsten Seiten:
B33: klare Strukturierung | E33: die erste Spalte "Nr." wird automatisch numeriert
B34: Man kann nur in den blauen Felder etwas eingeben | E34: Ja wurde ersetzt durch "X"; eine leere Zelle bedeutet "Nein"
B35: Formate von Zellen können nicht geändert werden | E35: Die Spalten VVL-Datum und WV-Datum werden nicht mehr gebraucht, dafür gibt es 3 neue Felder:
B36: es gibt keine verbunden Zellen mehr, die man nicht vernünftig kopieren kann | E36: Vorlauf: berechnet anhand des Anbieters, ob VVL-Datum 6 Monate oder 1 Monat vor Vertragsende liegt
B37: Checkbox beim Ansprechpartner macht jemanden zum "Hauptansprechpartner" | E37: VVL: automatisch berechnet aus Vertragsende und Vorlauf
B38: Notizen befinden sich auf der Hauptseite, die letzte Seite entfällt | E38: WV: automatisch berechnet aus Vertragsende und Vorlauf
B39: neues Feld "Kundennummer", das ist die Debitor-Nummer für die Buchhaltung | E39: Die neuen Spalten befinden sich testweise erstmal ganz rechts
E40: Ich halte es für möglich, die WV-Liste automatisiert zu erstellen, aber das ist eher ein entfernteres Ziel

Sheet 1
A1: Verträge von | C1: {=Fullname(Kunde!$B$4,Kunde!$B$5) & ", " & Kunde!$B$7} -> Friedrich von Lien AG, 27404 Zeven
A2: Vertrag | O2: Aktuell | T2: Vertragseingabe
A3: Nr. | B3: Rufnummer | C3: SIM-Nr | D3: Kundenkonto | E3: Kunden-Nr | F3: RV | G3: Künd. | H3: Multi Ultra | I3: Vertragsende | J3: VVL Datum | K3: WV Datum | L3: Nutzer | M3: Kost | N3: RG Form | O3: Anbieter | P3: Tarif aktuell | Q3: Option | R3: Option 2 | S3: Option 3 | T3: Aktiviert | U3: Tarif neu | V3: Handy | W3: Gutschrift | X3: RG-Nummer | Y3: Provision | Z3: Vorlauf | AA3: VVL | AB3: WV
A4: =ROW()-3 -> 1 | B4: 0175-4549654 | C4: 00001-61558916-8 | D4: 0061649340 | E4: 87027522 | F4: TM217 | I4: 44665 | J4: 44484 | K4: 44454 | N4: O | O4: D1 | P4: DCMBB | T4: 44614 | U4: DCMBB | Y4: 125 | Z4: {=Vorlauf(Tabelle1[[#This Row],[Anbieter]])} -> 6 | AA4: =IFERROR(EDATE(Tabelle1[[#This Row],[Vertragsende]], -Tabelle1[[#This Row],[Vorlauf]]) + 1, "") -> 44484 | AB4: =IFERROR(EDATE(Tabelle1[[#This Row],[Vertragsende]], -Tabelle1[[#This Row],[Vorlauf]] - 1) + 1, "") -> 44454
A5: =ROW()-3 -> 2 | B5: 0175-6013246 | C5: 00001-62625118-8 | D5: 0061649340 | E5: 87027522 | F5: TM217 | I5: 44665 | J5: 44484 | K5: 44454 | N5: O | O5: D1 | P5: DCMBB | T5: 44614 | U5: DCMBB | Y5: 125 | Z5: {=Vorlauf(Tabelle1[[#This Row],[Anbieter]])} -> 6 | AA5: =IFERROR(EDATE(Tabelle1[[#This Row],[Vertragsende]], -Tabelle1[[#This Row],[Vorlauf]]) + 1, "") -> 44484 | AB5: =IFERROR(EDATE(Tabelle1[[#This Row],[Vertragsende]], -Tabelle1[[#This Row],[Vorlauf]] - 1) + 1, "") -> 44454
A6: =ROW()-3 -> 3 | B6: 0175-6016444 | C6: 00001-61558918-4 | D6: 0061649340 | E6: 87027522 | F6: TM217 | I6: 44665 | J6: 44484 | K6: 44454 | N6: O | O6: D1 | P6: DCMBB | T6: 44614 | U6: DCMBB | Y6: 125 | Z6: {=Vorlauf(Tabelle1[[#This Row],[Anbieter]])} -> 6 | AA6: =IFERROR(EDATE(Tabelle1[[#This Row],[Vertragsende]], -Tabelle1[[#This Row],[Vorlauf]]) + 1, "") -> 44484 | AB6: =IFERROR(EDATE(Tabelle1[[#This Row],[Vertragsende]], -Tabelle1[[#This Row],[Vorlauf]] - 1) + 1, "") -> 44454
A7: =ROW()-3 -> 4 | B7: 0175-6028099 | C7: 00001-61558919-2 | D7: 0061649340 | E7: 87027522 | F7: TM217 | I7: 44665 | J7: 44484 | K7: 44454 | N7: O | O7: D1 | P7: DCMBB | T7: 44614 | U7: DCMBB | Y7: 125 | Z7: {=Vorlauf(Tabelle1[[#This Row],[Anbieter]])} -> 6 | AA7: =IFERROR(EDATE(Tabelle1[[#This Row],[Vertragsende]], -Tabelle1[[#This Row],[Vorlauf]]) + 1, "") -> 44484 | AB7: =IFERROR(EDATE(Tabelle1[[#This Row],[Vertragsende]], -Tabelle1[[#This Row],[Vorlauf]] - 1) + 1, "") -> 44454
A8: =ROW()-3 -> 5 | B8: 0175-6030029 | C8: 00001-63583428-9 | D8: 0061649340 | E8: 87027522 | F8: TM217 | I8: 44665 | J8: 44484 | K8: 44454 | N8: O | O8: D1 | P8: DCMBB | T8: 44614 | U8: DCMBB | Y8: 125 | Z8: {=Vorlauf(Tabelle1[[#This Row],[Anbieter]])} -> 6 | AA8: =IFERROR(EDATE(Tabelle1[[#This Row],[Vertragsende]], -Tabelle1[[#This Row],[Vorlauf]]) + 1, "") -> 44484 | AB8: =IFERROR(EDATE(Tabelle1[[#This Row],[Vertragsende]], -Tabelle1[[#This Row],[Vorlauf]] - 1) + 1, "") -> 44454
A9: =ROW()-3 -> 6 | B9: 0175-6030705 | C9: 00001-63583429-7 | D9: 0061649340 | E9: 87027522 | F9: TM217 | I9: 44665 | J9: 44484 | K9: 44454 | N9: O | O9: D1 | P9: DCMBB | T9: 44614 | U9: DCMBB | Y9: 125 | Z9: {=Vorlauf(Tabelle1[[#This Row],[Anbieter]])} -> 6 | AA9: =IFERROR(EDATE(Tabelle1[[#This Row],[Vertragsende]], -Tabelle1[[#This Row],[Vorlauf]]) + 1, "") -> 44484 | AB9: =IFERROR(EDATE(Tabelle1[[#This Row],[Vertragsende]], -Tabelle1[[#This Row],[Vorlauf]] - 1) + 1, "") -> 44454
A10: =ROW()-3 -> 7 | B10: 0175-6036922 | C10: 00001-63583430-5 | D10: 0061649340 | E10: 87027522 | F10: TM217 | I10: 44665 | J10: 44484 | K10: 44454 | N10: O | O10: D1 | P10: DCMBB | T10: 44614 | U10: DCMBB | Y10: 125 | Z10: {=Vorlauf(Tabelle1[[#This Row],[Anbieter]])} -> 6 | AA10: =IFERROR(EDATE(Tabelle1[[#This Row],[Vertragsende]], -Tabelle1[[#This Row],[Vorlauf]]) + 1, "") -> 44484 | AB10: =IFERROR(EDATE(Tabelle1[[#This Row],[Vertragsende]], -Tabelle1[[#This Row],[Vorlauf]] - 1) + 1, "") -> 44454
A11: =ROW()-3 -> 8 | B11: 0175-6041441 | C11: 00001-63583431-3 | D11: 0061649340 | E11: 87027522 | F11: TM217 | I11: 44665 | J11: 44484 | K11: 44454 | N11: O | O11: D1 | P11: DCMBB | T11: 44614 | U11: DCMBB | Y11: 125 | Z11: {=Vorlauf(Tabelle1[[#This Row],[Anbieter]])} -> 6 | AA11: =IFERROR(EDATE(Tabelle1[[#This Row],[Vertragsende]], -Tabelle1[[#This Row],[Vorlauf]]) + 1, "") -> 44484 | AB11: =IFERROR(EDATE(Tabelle1[[#This Row],[Vertragsende]], -Tabelle1[[#This Row],[Vorlauf]] - 1) + 1, "") -> 44454
A12: =ROW()-3 -> 9 | B12: 0175-6044274 | C12: 00001-63583432-1 | D12: 0061649340 | E12: 87027522 | F12: TM217 | I12: 44665 | J12: 44484 | K12: 44454 | N12: O | O12: D1 | P12: DCMBB | T12: 44614 | U12: DCMBB | Y12: 125 | Z12: {=Vorlauf(Tabelle1[[#This Row],[Anbieter]])} -> 6 | AA12: =IFERROR(EDATE(Tabelle1[[#This Row],[Vertragsende]], -Tabelle1[[#This Row],[Vorlauf]]) + 1, "") -> 44484 | AB12: =IFERROR(EDATE(Tabelle1[[#This Row],[Vertragsende]], -Tabelle1[[#This Row],[Vorlauf]] - 1) + 1, "") -> 44454
A13: =ROW()-3 -> 10 | B13: 0175-6050220 | C13: 00001-63583433-9 | D13: 0061649340 | E13: 87027522 | F13: TM217 | I13: 44665 | J13: 44484 | K13: 44454 | N13: O | O13: D1 | P13: DCMBB | T13: 44614 | U13: DCMBB | Y13: 125 | Z13: {=Vorlauf(Tabelle1[[#This Row],[Anbieter]])} -> 6 | AA13: =IFERROR(EDATE(Tabelle1[[#This Row],[Vertragsende]], -Tabelle1[[#This Row],[Vorlauf]]) + 1, "") -> 44484 | AB13: =IFERROR(EDATE(Tabelle1[[#This Row],[Vertragsende]], -Tabelle1[[#This Row],[Vorlauf]] - 1) + 1, "") -> 44454
A14: =ROW()-3 -> 11 | B14: 0175-6059733 | C14: 00001-63583434-7 | D14: 0061649340 | E14: 87027522 | F14: TM217 | I14: 44665 | J14: 44484 | K14: 44454 | N14: O | O14: D1 | P14: DCMBB | T14: 44614 | U14: DCMBB | Y14: 125 | Z14: {=Vorlauf(Tabelle1[[#This Row],[Anbieter]])} -> 6 | AA14: =IFERROR(EDATE(Tabelle1[[#This Row],[Vertragsende]], -Tabelle1[[#This Row],[Vorlauf]]) + 1, "") -> 44484 | AB14: =IFERROR(EDATE(Tabelle1[[#This Row],[Vertragsende]], -Tabelle1[[#This Row],[Vorlauf]] - 1) + 1, "") -> 44454
A15: =ROW()-3 -> 12 | B15: 0175-6061688 | C15: 00001-63583435-4 | D15: 0061649340 | E15: 87027522 | F15: TM217 | I15: 44665 | J15: 44484 | K15: 44454 | N15: O | O15: D1 | P15: DCMBB | T15: 44614 | U15: DCMBB | Y15: 125 | Z15: {=Vorlauf(Tabelle1[[#This Row],[Anbieter]])} -> 6 | AA15: =IFERROR(EDATE(Tabelle1[[#This Row],[Vertragsende]], -Tabelle1[[#This Row],[Vorlauf]]) + 1, "") -> 44484 | AB15: =IFERROR(EDATE(Tabelle1[[#This Row],[Vertragsende]], -Tabelle1[[#This Row],[Vorlauf]] - 1) + 1, "") -> 44454
... A45: =ROW()-3 -> 42 | B45: 0175-9012200 | C45: 00001-63583465-1 | D45: 0061649340 | E45: 87027522 | F45: TM217 | I45: 44665 | J45: 44484 | K45: 44454 | N45: O | O45: D1 | P45: DCMBB | T45: 44614 | U45: DCMBB | Y45: 125 | Z45: {=Vorlauf(Tabelle1[[#This Row],[Anbieter]])} -> 6 | AA45: =IFERROR(EDATE(Tabelle1[[#This Row],[Vertragsende]], -Tabelle1[[#This Row],[Vorlauf]]) + 1, "") -> 44484 | AB45: =IFERROR(EDATE(Tabelle1[[#This Row],[Vertragsende]], -Tabelle1[[#This Row],[Vorlauf]] - 1) + 1, "") -> 44454
A46: =ROW()-3 -> 43 | B46: 0176-34316593 | C46: 00001-62660116-8 | D46: 0061649340 | E46: 87027522 | F46: TM217 | H46: X | I46: 44684 | J46: 44504 | K46: 44473 | N46: O | O46: D1 | P46: BMSH3 | T46: 44617 | U46: BMSH3 | Y46: 240 | Z46: {=Vorlauf(Tabelle1[[#This Row],[Anbieter]])} -> 6 | AA46: =IFERROR(EDATE(Tabelle1[[#This Row],[Vertragsende]], -Tabelle1[[#This Row],[Vorlauf]]) + 1, "") -> 44504 | AB46: =IFERROR(EDATE(Tabelle1[[#This Row],[Vertragsende]], -Tabelle1[[#This Row],[Vorlauf]] - 1) + 1, "") -> 44473
A47: =ROW()-3 -> 44 | B47: 0176-34319589 | C47: 00001-62660117-6 | D47: 0061649340 | E47: 87027522 | F47: TM217 | H47: X | I47: 44684 | J47: 44504 | K47: 44473 | N47: O | O47: D1 | P47: BMSH3 | T47: 44617 | U47: BMSH3 | Y47: 240 | Z47: {=Vorlauf(Tabelle1[[#This Row],[Anbieter]])} -> 6 | AA47: =IFERROR(EDATE(Tabelle1[[#This Row],[Vertragsende]], -Tabelle1[[#This Row],[Vorlauf]]) + 1, "") -> 44504 | AB47: =IFERROR(EDATE(Tabelle1[[#This Row],[Vertragsende]], -Tabelle1[[#This Row],[Vorlauf]] - 1) + 1, "") -> 44473
A48: =ROW()-3 -> 45 | B48: 0176-34372893 | C48: 00001-62662120-8 | D48: 0061649340 | E48: 87027522 | F48: TM217 | H48: X | I48: 44684 | J48: 44504 | K48: 44473 | N48: O | O48: D1 | P48: BMSH3 | T48: 44617 | U48: BMSH3 | Y48: 240 | Z48: {=Vorlauf(Tabelle1[[#This Row],[Anbieter]])} -> 6 | AA48: =IFERROR(EDATE(Tabelle1[[#This Row],[Vertragsende]], -Tabelle1[[#This Row],[Vorlauf]]) + 1, "") -> 44504 | AB48: =IFERROR(EDATE(Tabelle1[[#This Row],[Vertragsende]], -Tabelle1[[#This Row],[Vorlauf]] - 1) + 1, "") -> 44473
A49: =ROW()-3 -> 46 | B49: 0176-45989519 | C49: 00001-62662477-2 | D49: 0061649340 | E49: 87027522 | F49: TM217 | I49: 44684 | J49: 44504 | K49: 44473 | N49: O | O49: D1 | P49: BMSH3 | T49: 44617 | U49: BMSH3 | Y49: 240 | Z49: {=Vorlauf(Tabelle1[[#This Row],[Anbieter]])} -> 6 | AA49: =IFERROR(EDATE(Tabelle1[[#This Row],[Vertragsende]], -Tabelle1[[#This Row],[Vorlauf]]) + 1, "") -> 44504 | AB49: =IFERROR(EDATE(Tabelle1[[#This Row],[Vertragsende]], -Tabelle1[[#This Row],[Vorlauf]] - 1) + 1, "") -> 44473
A50: =ROW()-3 -> 47 | B50: 0176-45989521 | C50: 00001-62662475-6 | D50: 0061649340 | E50: 87027522 | F50: TM217 | I50: 44684 | J50: 44504 | K50: 44473 | N50: O | O50: D1 | P50: BMSH3 | T50: 44617 | U50: BMSH3 | Y50: 240 | Z50: {=Vorlauf(Tabelle1[[#This Row],[Anbieter]])} -> 6 | AA50: =IFERROR(EDATE(Tabelle1[[#This Row],[Vertragsende]], -Tabelle1[[#This Row],[Vorlauf]]) + 1, "") -> 44504 | AB50: =IFERROR(EDATE(Tabelle1[[#This Row],[Vertragsende]], -Tabelle1[[#This Row],[Vorlauf]] - 1) + 1, "") -> 44473
A51: =ROW()-3 -> 48 | B51: 0176-45989542 | C51: 00001-62662476-4 | D51: 0061649340 | E51: 87027522 | F51: TM217 | I51: 44684 | J51: 44504 | K51: 44473 | N51: O | O51: D1 | P51: BMSH3 | T51: 44617 | U51: BMSH3 | Y51: 240 | Z51: {=Vorlauf(Tabelle1[[#This Row],[Anbieter]])} -> 6 | AA51: =IFERROR(EDATE(Tabelle1[[#This Row],[Vertragsende]], -Tabelle1[[#This Row],[Vorlauf]]) + 1, "") -> 44504 | AB51: =IFERROR(EDATE(Tabelle1[[#This Row],[Vertragsende]], -Tabelle1[[#This Row],[Vorlauf]] - 1) + 1, "") -> 44473
A52: =ROW()-3 -> 49 | B52: 0176-47117018 | C52: 00001-63593362-8 | D52: 0061649340 | E52: 87027522 | F52: TM217 | H52: X | I52: 44684 | J52: 44504 | K52: 44473 | N52: O | O52: D1 | P52: BMSH3 | T52: 44617 | U52: BMSH3 | Y52: 240 | Z52: {=Vorlauf(Tabelle1[[#This Row],[Anbieter]])} -> 6 | AA52: =IFERROR(EDATE(Tabelle1[[#This Row],[Vertragsende]], -Tabelle1[[#This Row],[Vorlauf]]) + 1, "") -> 44504 | AB52: =IFERROR(EDATE(Tabelle1[[#This Row],[Vertragsende]], -Tabelle1[[#This Row],[Vorlauf]] - 1) + 1, "") -> 44473
A53: =ROW()-3 -> 50 | B53: 0176-56788683 | C53: 00001-63593442-8 | D53: 0061649340 | E53: 87027522 | F53: TM217 | I53: 44684 | J53: 44504 | K53: 44473 | N53: O | O53: D1 | P53: BMSH3 | T53: 44617 | U53: BMSH3 | Y53: 240 | Z53: {=Vorlauf(Tabelle1[[#This Row],[Anbieter]])} -> 6 | AA53: =IFERROR(EDATE(Tabelle1[[#This Row],[Vertragsende]], -Tabelle1[[#This Row],[Vorlauf]]) + 1, "") -> 44504 | AB53: =IFERROR(EDATE(Tabelle1[[#This Row],[Vertragsende]], -Tabelle1[[#This Row],[Vorlauf]] - 1) + 1, "") -> 44473
A54: =ROW()-3 -> 51 | B54: 0176-57868667 | C54: 00001-62662032-5 | D54: 0061649340 | E54: 87027522 | F54: TM217 | I54: 44684 | J54: 44504 | K54: 44473 | N54: O | O54: D1 | P54: BMSH3 | T54: 44617 | U54: BMSH3 | Y54: 240 | Z54: {=Vorlauf(Tabelle1[[#This Row],[Anbieter]])} -> 6 | AA54: =IFERROR(EDATE(Tabelle1[[#This Row],[Vertragsende]], -Tabelle1[[#This Row],[Vorlauf]]) + 1, "") -> 44504 | AB54: =IFERROR(EDATE(Tabelle1[[#This Row],[Vertragsende]], -Tabelle1[[#This Row],[Vorlauf]] - 1) + 1, "") -> 44473
A55: =ROW()-3 -> 52 | B55: 0176-71211976 | C55: 00001-62660003-8 | D55: 0061649340 | E55: 87027522 | F55: TM217 | I55: 44684 | J55: 44504 | K55: 44473 | N55: O | O55: D1 | P55: BMSH3 | T55: 44617 | U55: BMSH3 | Y55: 240 | Z55: {=Vorlauf(Tabelle1[[#This Row],[Anbieter]])} -> 6 | AA55: =IFERROR(EDATE(Tabelle1[[#This Row],[Vertragsende]], -Tabelle1[[#This Row],[Vorlauf]]) + 1, "") -> 44504 | AB55: =IFERROR(EDATE(Tabelle1[[#This Row],[Vertragsende]], -Tabelle1[[#This Row],[Vorlauf]] - 1) + 1, "") -> 44473
A56: =ROW()-3 -> 53 | B56: 0151-16726447 | C56: 00001-64459175-5 | D56: 0061649340 | E56: 87027522 | F56: TM217 | I56: 44737 | J56: 44556 | K56: 44526 | N56: O | O56: D1 | P56: DCMBB | T56: 44617 | U56: BMDSH | Y56: 165 | Z56: {=Vorlauf(Tabelle1[[#This Row],[Anbieter]])} -> 6 | AA56: =IFERROR(EDATE(Tabelle1[[#This Row],[Vertragsende]], -Tabelle1[[#This Row],[Vorlauf]]) + 1, "") -> 44556 | AB56: =IFERROR(EDATE(Tabelle1[[#This Row],[Vertragsende]], -Tabelle1[[#This Row],[Vorlauf]] - 1) + 1, "") -> 44526
A57: =ROW()-3 -> 54 | B57: 0151-18954341 | C57: 00001-64459176-3 | D57: 0061649340 | E57: 87027522 | F57: TM217 | I57: 44737 | J57: 44556 | K57: 44526 | N57: O | O57: D1 | P57: DCMBB | T57: 44617 | U57: BMDSH | Y57: 165 | Z57: {=Vorlauf(Tabelle1[[#This Row],[Anbieter]])} -> 6 | AA57: =IFERROR(EDATE(Tabelle1[[#This Row],[Vertragsende]], -Tabelle1[[#This Row],[Vorlauf]]) + 1, "") -> 44556 | AB57: =IFERROR(EDATE(Tabelle1[[#This Row],[Vertragsende]], -Tabelle1[[#This Row],[Vorlauf]] - 1) + 1, "") -> 44526
A58: =ROW()-3 -> 55 | B58: 0151-18956409 | C58: 00001-64459177-1 | D58: 0061649340 | E58: 87027522 | F58: TM217 | I58: 44737 | J58: 44556 | K58: 44526 | N58: O | O58: D1 | P58: DCMBB | T58: 44617 | U58: BMDSH | Y58: 165 | Z58: {=Vorlauf(Tabelle1[[#This Row],[Anbieter]])} -> 6 | AA58: =IFERROR(EDATE(Tabelle1[[#This Row],[Vertragsende]], -Tabelle1[[#This Row],[Vorlauf]]) + 1, "") -> 44556 | AB58: =IFERROR(EDATE(Tabelle1[[#This Row],[Vertragsende]], -Tabelle1[[#This Row],[Vorlauf]] - 1) + 1, "") -> 44526
A59: =ROW()-3 -> 56 | B59: 0151-18991257 | C59: 00001-64459187-9 | D59: 0061649340 | E59: 87027522 | F59: TM217 | I59: 44737 | J59: 44556 | K59: 44526 | N59: O | O59: D1 | P59: DCMBB | T59: 44617 | U59: BMDSH | Y59: 165 | Z59: {=Vorlauf(Tabelle1[[#This Row],[Anbieter]])} -> 6 | AA59: =IFERROR(EDATE(Tabelle1[[#This Row],[Vertragsende]], -Tabelle1[[#This Row],[Vorlauf]]) + 1, "") -> 44556 | AB59: =IFERROR(EDATE(Tabelle1[[#This Row],[Vertragsende]], -Tabelle1[[#This Row],[Vorlauf]] - 1) + 1, "") -> 44526
A60: =ROW()-3 -> 57 | B60: 0151-18992815 | C60: 00001-64459179-7 | D60: 0061649340 | E60: 87027522 | F60: TM217 | I60: 44737 | J60: 44556 | K60: 44526 | N60: O | O60: D1 | P60: DCMBB | T60: 44617 | U60: BMDSH | Y60: 165 | Z60: {=Vorlauf(Tabelle1[[#This Row],[Anbieter]])} -> 6 | AA60: =IFERROR(EDATE(Tabelle1[[#This Row],[Vertragsende]], -Tabelle1[[#This Row],[Vorlauf]]) + 1, "") -> 44556 | AB60: =IFERROR(EDATE(Tabelle1[[#This Row],[Vertragsende]], -Tabelle1[[#This Row],[Vorlauf]] - 1) + 1, "") -> 44526
A61: =ROW()-3 -> 58 | B61: 0170-2212909 | C61: 00001-64462476-2 | D61: 0061649340 | E61: 87027522 | F61: TM217 | I61: 44756 | J61: 44576 | K61: 44545 | N61: O | O61: D1 | P61: BMSH3 | T61: 44617 | U61: BMSH3 | Y61: 240 | Z61: {=Vorlauf(Tabelle1[[#This Row],[Anbieter]])} -> 6 | AA61: =IFERROR(EDATE(Tabelle1[[#This Row],[Vertragsende]], -Tabelle1[[#This Row],[Vorlauf]]) + 1, "") -> 44576 | AB61: =IFERROR(EDATE(Tabelle1[[#This Row],[Vertragsende]], -Tabelle1[[#This Row],[Vorlauf]] - 1) + 1, "") -> 44545
A62: =ROW()-3 -> 59 | B62: 0151-16739957 | C62: 00001-64825065-5 | D62: 0061649340 | E62: 87027522 | F62: TM217 | I62: 44791 | J62: 44611 | K62: 44580 | N62: O | O62: D1 | P62: BMSH3 | T62: 44691 | U62: BMSH3 | V62: Samsung Galaxy A52s 5G 256GB schwarz | Y62: 50 | Z62: {=Vorlauf(Tabelle1[[#This Row],[Anbieter]])} -> 6 | AA62: =IFERROR(EDATE(Tabelle1[[#This Row],[Vertragsende]], -Tabelle1[[#This Row],[Vorlauf]]) + 1, "") -> 44611 | AB62: =IFERROR(EDATE(Tabelle1[[#This Row],[Vertragsende]], -Tabelle1[[#This Row],[Vorlauf]] - 1) + 1, "") -> 44580
A63: =ROW()-3 -> 60 | B63: 0151-67962659 | C63: 00001-66317441-8 | D63: 0061649340 | E63: 87027522 | F63: TM217 | I63: 44797 | J63: 44617 | K63: 44586 | N63: O | O63: D1 | P63: BMSH3 | T63: 44732 | U63: BMSH3 | Y63: 240 | Z63: {=Vorlauf(Tabelle1[[#This Row],[Anbieter]])} -> 6 | AA63: =IFERROR(EDATE(Tabelle1[[#This Row],[Vertragsende]], -Tabelle1[[#This Row],[Vorlauf]]) + 1, "") -> 44617 | AB63: =IFERROR(EDATE(Tabelle1[[#This Row],[Vertragsende]], -Tabelle1[[#This Row],[Vorlauf]] - 1) + 1, "") -> 44586
A64: =ROW()-3 -> 61 | B64: 0151-55231475 | C64: 00001-64836897-8 | D64: 0061649340 | E64: 87027522 | F64: TM217 | I64: 44803 | J64: 44620 | K64: 44589 | N64: O | O64: D1 | P64: BMSH3 | T64: 44732 | U64: BMSH3 | Y64: 240 | Z64: {=Vorlauf(Tabelle1[[#This Row],[Anbieter]])} -> 6 | AA64: =IFERROR(EDATE(Tabelle1[[#This Row],[Vertragsende]], -Tabelle1[[#This Row],[Vorlauf]]) + 1, "") -> 44621 | AB64: =IFERROR(EDATE(Tabelle1[[#This Row],[Vertragsende]], -Tabelle1[[#This Row],[Vorlauf]] - 1) + 1, "") -> 44592
A65: =ROW()-3 -> 62 | B65: 0176-43242079 | C65: 00001-64903527-9 | D65: 0061649340 | E65: 87027522 | F65: TM217 | I65: 44866 | J65: 44683 | K65: 44653 | N65: O | O65: D1 | P65: BMSH3 | T65: 44749 | U65: BMSH3 | V65: Samsung Galaxy A53 5G 128GB Blau | Y65: 50 | Z65: {=Vorlauf(Tabelle1[[#This Row],[Anbieter]])} -> 6 | AA65: =IFERROR(EDATE(Tabelle1[[#This Row],[Vertragsende]], -Tabelle1[[#This Row],[Vorlauf]]) + 1, "") -> 44683 | AB65: =IFERROR(EDATE(Tabelle1[[#This Row],[Vertragsende]], -Tabelle1[[#This Row],[Vorlauf]] - 1) + 1, "") -> 44653
A66: =ROW()-3 -> 63 | B66: 0160-92336095 | C66: 00001-70010149-9 | D66: 0061649340 | E66: 87027522 | F66: TM217 | I66: 44902 | J66: 44720 | K66: 44689 | N66: O | O66: D1 | P66: DCMBB | T66: 44841 | U66: BMDSH | Y66: 165 | Z66: {=Vorlauf(Tabelle1[[#This Row],[Anbieter]])} -> 6 | AA66: =IFERROR(EDATE(Tabelle1[[#This Row],[Vertragsende]], -Tabelle1[[#This Row],[Vorlauf]]) + 1, "") -> 44720 | AB66: =IFERROR(EDATE(Tabelle1[[#This Row],[Vertragsende]], -Tabelle1[[#This Row],[Vorlauf]] - 1) + 1, "") -> 44689
A67: =ROW()-3 -> 64 | B67: 0151-17246172 | C67: 00001-82611594-4 | D67: 0061649340 | E67: 87027522 | F67: TM217 | I67: 44982 | J67: 44799 | K67: 44743 | N67: O | O67: D1 | P67: BMSH3 | T67: 44841 | U67: BMSH3 | V67: Samsung Galaxy A54 5G 256GB Awesome Graphite | Y67: 190 | Z67: {=Vorlauf(Tabelle1[[#This Row],[Anbieter]])} -> 6 | AA67: =IFERROR(EDATE(Tabelle1[[#This Row],[Vertragsende]], -Tabelle1[[#This Row],[Vorlauf]]) + 1, "") -> 44799 | AB67: =IFERROR(EDATE(Tabelle1[[#This Row],[Vertragsende]], -Tabelle1[[#This Row],[Vorlauf]] - 1) + 1, "") -> 44768
A68: =ROW()-3 -> 65 | B68: 0151-18912809 | C68: 00001-66231147-4 | D68: 0061649340 | E68: 87027522 | F68: TM217 | H68: X | I68: 44982 | J68: 44799 | K68: 44743 | N68: O | O68: D1 | P68: BMSH3 | T68: 44841 | U68: BMSH3 | Y68: 190 | Z68: {=Vorlauf(Tabelle1[[#This Row],[Anbieter]])} -> 6 | AA68: =IFERROR(EDATE(Tabelle1[[#This Row],[Vertragsende]], -Tabelle1[[#This Row],[Vorlauf]]) + 1, "") -> 44799 | AB68: =IFERROR(EDATE(Tabelle1[[#This Row],[Vertragsende]], -Tabelle1[[#This Row],[Vorlauf]] - 1) + 1, "") -> 44768
A69: =ROW()-3 -> 66 | B69: 0179-4182427 | E69: I0512586 | G69: X | I69: 44834 | K69: 44774 | N69: O | O69: Drillisch | T69: 44834 | U69: BMSH3 | V69: Samsung Galaxy A53 5G 256GB Schwarz | Y69: 365 | Z69: {=Vorlauf(Tabelle1[[#This Row],[Anbieter]])} -> 1 | AA69: =IFERROR(EDATE(Tabelle1[[#This Row],[Vertragsende]], -Tabelle1[[#This Row],[Vorlauf]]) + 1, "") -> 44804 | AB69: =IFERROR(EDATE(Tabelle1[[#This Row],[Vertragsende]], -Tabelle1[[#This Row],[Vorlauf]] - 1) + 1, "") -> 44773
...

Sheet 2
A1: Verträge von | C1: {=Fullname(Kunde!$B$4,Kunde!$B$5) & ", " & Kunde!$B$7} -> Friedrich von Lien AG, 27404 Zeven
A2: Vertrag | O2: Aktuell | U2: Vertragseingabe
A3: Nr. | B3: Rufnummer | C3: SIM-Nr | D3: Kundenkonto | E3: Kunden-Nr | F3: RV | G3: Künd. | H3: Multi Ultra | I3: Vertragsende | J3: VVL | K3: WV | L3: Nutzer | M3: Kost | N3: RG Form | O3: Anbieter | P3: Tarif aktuell | Q3: Option 1 | R3: Option 2 | S3: Option 3 | T3: Option 4 | U3: Aktiviert | V3: Tarif neu | W3: Handy | X3: Gutschrift | Y3: RG-Nummer | Z3: Provision | AA3: Vorlauf | AB3: Test VVL | AC3: Test WV
A4: =ROW()-3 -> 1 | B4: 0171-2120735 | C4: 00001-77887291-4 | D4: 0061649340 | E4: 87027522 | F4: TM217 | H4: X | I4: 45394 | J4: 45212 | K4: 45170 | N4: O | O4: TM | P4: BMSH3 | U4: 45248 | V4: BMMSH3 | W4: iPhone 15 256GB Schwarz | Z4: 265 | AA4: {=Vorlauf(Tabelle13[[#This Row],[Anbieter]])} -> 6 | AB4: =IFERROR(EDATE(Tabelle13[[#This Row],[Vertragsende]], -Tabelle13[[#This Row],[Vorlauf]]) + 1,"") -> 45212 | AC4: =IFERROR(EDATE(Tabelle13[[#This Row],[Vertragsende]], -Tabelle13[[#This Row],[Vorlauf]] - 1) + 1,"") -> 45182
A5: =ROW()-3 -> 2 | B5: 0175-4549654 | C5: 00001-61558916-8 | D5: 0061649340 | E5: 87027522 | F5: TM217 | I5: 45396 | J5: 45214 | K5: 45170 | N5: O | O5: TM | P5: DCMBB | U5: 45248 | V5: BMDSH | Z5: 165 | AA5: {=Vorlauf(Tabelle13[[#This Row],[Anbieter]])} -> 6 | AB5: =IFERROR(EDATE(Tabelle13[[#This Row],[Vertragsende]], -Tabelle13[[#This Row],[Vorlauf]]) + 1,"") -> 45214 | AC5: =IFERROR(EDATE(Tabelle13[[#This Row],[Vertragsende]], -Tabelle13[[#This Row],[Vorlauf]] - 1) + 1,"") -> 45184
A6: =ROW()-3 -> 3 | B6: 0175-6013246 | C6: 00001-62625118-8 | D6: 0061649340 | E6: 87027522 | F6: TM217 | I6: 45396 | J6: 45214 | K6: 45170 | N6: O | O6: TM | P6: DCMBB | U6: 45248 | V6: BMDSH | Z6: 165 | AA6: {=Vorlauf(Tabelle13[[#This Row],[Anbieter]])} -> 6 | AB6: =IFERROR(EDATE(Tabelle13[[#This Row],[Vertragsende]], -Tabelle13[[#This Row],[Vorlauf]]) + 1,"") -> 45214 | AC6: =IFERROR(EDATE(Tabelle13[[#This Row],[Vertragsende]], -Tabelle13[[#This Row],[Vorlauf]] - 1) + 1,"") -> 45184
A7: =ROW()-3 -> 4 | B7: 0175-6016444 | C7: 00001-61558918-4 | D7: 0061649340 | E7: 87027522 | F7: TM217 | I7: 45396 | J7: 45214 | K7: 45170 | N7: O | O7: TM | P7: DCMBB | U7: 45248 | V7: BMDSH | Z7: 165 | AA7: {=Vorlauf(Tabelle13[[#This Row],[Anbieter]])} -> 6 | AB7: =IFERROR(EDATE(Tabelle13[[#This Row],[Vertragsende]], -Tabelle13[[#This Row],[Vorlauf]]) + 1,"") -> 45214 | AC7: =IFERROR(EDATE(Tabelle13[[#This Row],[Vertragsende]], -Tabelle13[[#This Row],[Vorlauf]] - 1) + 1,"") -> 45184
A8: =ROW()-3 -> 5 | B8: 0175-6028099 | C8: 00001-61558919-2 | D8: 0061649340 | E8: 87027522 | F8: TM217 | I8: 45396 | J8: 45214 | K8: 45170 | N8: O | O8: TM | P8: DCMBB | U8: 45248 | V8: BMDSH | Z8: 165 | AA8: {=Vorlauf(Tabelle13[[#This Row],[Anbieter]])} -> 6 | AB8: =IFERROR(EDATE(Tabelle13[[#This Row],[Vertragsende]], -Tabelle13[[#This Row],[Vorlauf]]) + 1,"") -> 45214 | AC8: =IFERROR(EDATE(Tabelle13[[#This Row],[Vertragsende]], -Tabelle13[[#This Row],[Vorlauf]] - 1) + 1,"") -> 45184
A9: =ROW()-3 -> 6 | B9: 0175-6030029 | C9: 00001-63583428-9 | D9: 0061649340 | E9: 87027522 | F9: TM217 | I9: 45396 | J9: 45214 | K9: 45170 | N9: O | O9: TM | P9: DCMBB | U9: 45248 | V9: BMDSH | Z9: 165 | AA9: {=Vorlauf(Tabelle13[[#This Row],[Anbieter]])} -> 6 | AB9: =IFERROR(EDATE(Tabelle13[[#This Row],[Vertragsende]], -Tabelle13[[#This Row],[Vorlauf]]) + 1,"") -> 45214 | AC9: =IFERROR(EDATE(Tabelle13[[#This Row],[Vertragsende]], -Tabelle13[[#This Row],[Vorlauf]] - 1) + 1,"") -> 45184
A10: =ROW()-3 -> 7 | B10: 0175-6030705 | C10: 00001-63583429-7 | D10: 0061649340 | E10: 87027522 | F10: TM217 | I10: 45396 | J10: 45214 | K10: 45170 | N10: O | O10: TM | P10: DCMBB | U10: 45248 | V10: BMDSH | Z10: 165 | AA10: {=Vorlauf(Tabelle13[[#This Row],[Anbieter]])} -> 6 | AB10: =IFERROR(EDATE(Tabelle13[[#This Row],[Vertragsende]], -Tabelle13[[#This Row],[Vorlauf]]) + 1,"") -> 45214 | AC10: =IFERROR(EDATE(Tabelle13[[#This Row],[Vertragsende]], -Tabelle13[[#This Row],[Vorlauf]] - 1) + 1,"") -> 45184
A11: =ROW()-3 -> 8 | B11: 0175-6036922 | C11: 00001-63583430-5 | D11: 0061649340 | E11: 87027522 | F11: TM217 | I11: 45396 | J11: 45214 | K11: 45170 | N11: O | O11: TM | P11: DCMBB | U11: 45248 | V11: BMDSH | Z11: 165 | AA11: {=Vorlauf(Tabelle13[[#This Row],[Anbieter]])} -> 6 | AB11: =IFERROR(EDATE(Tabelle13[[#This Row],[Vertragsende]], -Tabelle13[[#This Row],[Vorlauf]]) + 1,"") -> 45214 | AC11: =IFERROR(EDATE(Tabelle13[[#This Row],[Vertragsende]], -Tabelle13[[#This Row],[Vorlauf]] - 1) + 1,"") -> 45184
A12: =ROW()-3 -> 9 | B12: 0175-6041441 | C12: 00001-63583431-3 | D12: 0061649340 | E12: 87027522 | F12: TM217 | I12: 45396 | J12: 45214 | K12: 45170 | N12: O | O12: TM | P12: DCMBB | U12: 45248 | V12: BMDSH | Z12: 165 | AA12: {=Vorlauf(Tabelle13[[#This Row],[Anbieter]])} -> 6 | AB12: =IFERROR(EDATE(Tabelle13[[#This Row],[Vertragsende]], -Tabelle13[[#This Row],[Vorlauf]]) + 1,"") -> 45214 | AC12: =IFERROR(EDATE(Tabelle13[[#This Row],[Vertragsende]], -Tabelle13[[#This Row],[Vorlauf]] - 1) + 1,"") -> 45184
A13: =ROW()-3 -> 10 | B13: 0175-6044274 | C13: 00001-63583432-1 | D13: 0061649340 | E13: 87027522 | F13: TM217 | I13: 45396 | J13: 45214 | K13: 45170 | N13: O | O13: TM | P13: DCMBB | U13: 45248 | V13: BMDSH | Z13: 165 | AA13: {=Vorlauf(Tabelle13[[#This Row],[Anbieter]])} -> 6 | AB13: =IFERROR(EDATE(Tabelle13[[#This Row],[Vertragsende]], -Tabelle13[[#This Row],[Vorlauf]]) + 1,"") -> 45214 | AC13: =IFERROR(EDATE(Tabelle13[[#This Row],[Vertragsende]], -Tabelle13[[#This Row],[Vorlauf]] - 1) + 1,"") -> 45184
A14: =ROW()-3 -> 11 | B14: 0175-6050220 | C14: 00001-63583433-9 | D14: 0061649340 | E14: 87027522 | F14: TM217 | I14: 45396 | J14: 45214 | K14: 45170 | N14: O | O14: TM | P14: DCMBB | U14: 45248 | V14: BMDSH | Z14: 165 | AA14: {=Vorlauf(Tabelle13[[#This Row],[Anbieter]])} -> 6 | AB14: =IFERROR(EDATE(Tabelle13[[#This Row],[Vertragsende]], -Tabelle13[[#This Row],[Vorlauf]]) + 1,"") -> 45214 | AC14: =IFERROR(EDATE(Tabelle13[[#This Row],[Vertragsende]], -Tabelle13[[#This Row],[Vorlauf]] - 1) + 1,"") -> 45184
A15: =ROW()-3 -> 12 | B15: 0175-6059733 | C15: 00001-63583434-7 | D15: 0061649340 | E15: 87027522 | F15: TM217 | I15: 45396 | J15: 45214 | K15: 45170 | N15: O | O15: TM | P15: DCMBB | U15: 45248 | V15: BMDSH | Z15: 165 | AA15: {=Vorlauf(Tabelle13[[#This Row],[Anbieter]])} -> 6 | AB15: =IFERROR(EDATE(Tabelle13[[#This Row],[Vertragsende]], -Tabelle13[[#This Row],[Vorlauf]]) + 1,"") -> 45214 | AC15: =IFERROR(EDATE(Tabelle13[[#This Row],[Vertragsende]], -Tabelle13[[#This Row],[Vorlauf]] - 1) + 1,"") -> 45184
A16: =ROW()-3 -> 13 | B16: 0175-6061688 | C16: 00001-63583435-4 | D16: 0061649340 | E16: 87027522 | F16: TM217 | I16: 45396 | J16: 45214 | K16: 45170 | N16: O | O16: TM | P16: DCMBB | U16: 45248 | V16: BMDSH | Z16: 165 | AA16: {=Vorlauf(Tabelle13[[#This Row],[Anbieter]])} -> 6 | AB16: =IFERROR(EDATE(Tabelle13[[#This Row],[Vertragsende]], -Tabelle13[[#This Row],[Vorlauf]]) + 1,"") -> 45214 | AC16: =IFERROR(EDATE(Tabelle13[[#This Row],[Vertragsende]], -Tabelle13[[#This Row],[Vorlauf]] - 1) + 1,"") -> 45184
... A46: =ROW()-3 -> 43 | B46: 0175-9012200 | C46: 00001-63583465-1 | D46: 0061649340 | E46: 87027522 | F46: TM217 | I46: 45396 | J46: 45214 | K46: 45170 | N46: O | O46: TM | P46: DCMBB | U46: 45248 | V46: BMDSH | Z46: 165 | AA46: {=Vorlauf(Tabelle13[[#This Row],[Anbieter]])} -> 6 | AB46: =IFERROR(EDATE(Tabelle13[[#This Row],[Vertragsende]], -Tabelle13[[#This Row],[Vorlauf]]) + 1,"") -> 45214 | AC46: =IFERROR(EDATE(Tabelle13[[#This Row],[Vertragsende]], -Tabelle13[[#This Row],[Vorlauf]] - 1) + 1,"") -> 45184
A47: =ROW()-3 -> 44 | B47: 0176-34316593 | C47: 00001-62660116-8 | D47: 0061649340 | E47: 87027522 | F47: TM217 | H47: X | I47: 45415 | J47: 45234 | K47: 45200 | N47: O | O47: TM | P47: BMSH3 | U47: 45248 | V47: BMMSH3 | Z47: 265 | AA47: {=Vorlauf(Tabelle13[[#This Row],[Anbieter]])} -> 6 | AB47: =IFERROR(EDATE(Tabelle13[[#This Row],[Vertragsende]], -Tabelle13[[#This Row],[Vorlauf]]) + 1,"") -> 45234 | AC47: =IFERROR(EDATE(Tabelle13[[#This Row],[Vertragsende]], -Tabelle13[[#This Row],[Vorlauf]] - 1) + 1,"") -> 45203
A48: =ROW()-3 -> 45 | B48: 0176-34319589 | C48: 00001-62660117-6 | D48: 0061649340 | E48: 87027522 | F48: TM217 | H48: X | I48: 45415 | J48: 45234 | K48: 45200 | N48: O | O48: TM | P48: BMSH3 | U48: 45248 | V48: BMMSH3 | Z48: 265 | AA48: {=Vorlauf(Tabelle13[[#This Row],[Anbieter]])} -> 6 | AB48: =IFERROR(EDATE(Tabelle13[[#This Row],[Vertragsende]], -Tabelle13[[#This Row],[Vorlauf]]) + 1,"") -> 45234 | AC48: =IFERROR(EDATE(Tabelle13[[#This Row],[Vertragsende]], -Tabelle13[[#This Row],[Vorlauf]] - 1) + 1,"") -> 45203
A49: =ROW()-3 -> 46 | B49: 0176-34372893 | C49: 00001-62662120-8 | D49: 0061649340 | E49: 87027522 | F49: TM217 | H49: X | I49: 45415 | J49: 45234 | K49: 45200 | N49: O | O49: TM | P49: BMSH3 | U49: 45248 | V49: BMMSH3 | Z49: 265 | AA49: {=Vorlauf(Tabelle13[[#This Row],[Anbieter]])} -> 6 | AB49: =IFERROR(EDATE(Tabelle13[[#This Row],[Vertragsende]], -Tabelle13[[#This Row],[Vorlauf]]) + 1,"") -> 45234 | AC49: =IFERROR(EDATE(Tabelle13[[#This Row],[Vertragsende]], -Tabelle13[[#This Row],[Vorlauf]] - 1) + 1,"") -> 45203
A50: =ROW()-3 -> 47 | B50: 0176-45989519 | C50: 00001-62662477-2 | D50: 0061649340 | E50: 87027522 | F50: TM217 | H50: X | I50: 45415 | J50: 45234 | K50: 45200 | N50: O | O50: TM | P50: BMSH3 | U50: 45248 | V50: BMMSH3 | Z50: 265 | AA50: {=Vorlauf(Tabelle13[[#This Row],[Anbieter]])} -> 6 | AB50: =IFERROR(EDATE(Tabelle13[[#This Row],[Vertragsende]], -Tabelle13[[#This Row],[Vorlauf]]) + 1,"") -> 45234 | AC50: =IFERROR(EDATE(Tabelle13[[#This Row],[Vertragsende]], -Tabelle13[[#This Row],[Vorlauf]] - 1) + 1,"") -> 45203
A51: =ROW()-3 -> 48 | B51: 0176-45989521 | C51: 00001-62662475-6 | D51: 0061649340 | E51: 87027522 | F51: TM217 | H51: X | I51: 45415 | J51: 45234 | K51: 45200 | N51: O | O51: TM | P51: BMSH3 | U51: 45248 | V51: BMMSH3 | Z51: 265 | AA51: {=Vorlauf(Tabelle13[[#This Row],[Anbieter]])} -> 6 | AB51: =IFERROR(EDATE(Tabelle13[[#This Row],[Vertragsende]], -Tabelle13[[#This Row],[Vorlauf]]) + 1,"") -> 45234 | AC51: =IFERROR(EDATE(Tabelle13[[#This Row],[Vertragsende]], -Tabelle13[[#This Row],[Vorlauf]] - 1) + 1,"") -> 45203
A52: =ROW()-3 -> 49 | B52: 0176-45989542 | C52: 00001-62662476-4 | D52: 0061649340 | E52: 87027522 | F52: TM217 | H52: X | I52: 45415 | J52: 45234 | K52: 45200 | N52: O | O52: TM | P52: BMSH3 | U52: 45248 | V52: BMMSH3 | Z52: 265 | AA52: {=Vorlauf(Tabelle13[[#This Row],[Anbieter]])} -> 6 | AB52: =IFERROR(EDATE(Tabelle13[[#This Row],[Vertragsende]], -Tabelle13[[#This Row],[Vorlauf]]) + 1,"") -> 45234 | AC52: =IFERROR(EDATE(Tabelle13[[#This Row],[Vertragsende]], -Tabelle13[[#This Row],[Vorlauf]] - 1) + 1,"") -> 45203
A53: =ROW()-3 -> 50 | B53: 0176-47117018 | C53: 00001-63593362-8 | D53: 0061649340 | E53: 87027522 | F53: TM217 | H53: X | I53: 45415 | J53: 45234 | K53: 45200 | N53: O | O53: TM | P53: BMSH3 | Q53: CF1+ | U53: 45248 | V53: BMMSH3 | Z53: 265 | AA53: {=Vorlauf(Tabelle13[[#This Row],[Anbieter]])} -> 6 | AB53: =IFERROR(EDATE(Tabelle13[[#This Row],[Vertragsende]], -Tabelle13[[#This Row],[Vorlauf]]) + 1,"") -> 45234 | AC53: =IFERROR(EDATE(Tabelle13[[#This Row],[Vertragsende]], -Tabelle13[[#This Row],[Vorlauf]] - 1) + 1,"") -> 45203
A54: =ROW()-3 -> 51 | B54: 0176-56788683 | C54: 00001-63593442-8 | D54: 0061649340 | E54: 87027522 | F54: TM217 | H54: X | I54: 45415 | J54: 45234 | K54: 45200 | N54: O | O54: TM | P54: BMSH3 | U54: 45248 | V54: BMSH3 | Z54: 170 | AA54: {=Vorlauf(Tabelle13[[#This Row],[Anbieter]])} -> 6 | AB54: =IFERROR(EDATE(Tabelle13[[#This Row],[Vertragsende]], -Tabelle13[[#This Row],[Vorlauf]]) + 1,"") -> 45234 | AC54: =IFERROR(EDATE(Tabelle13[[#This Row],[Vertragsende]], -Tabelle13[[#This Row],[Vorlauf]] - 1) + 1,"") -> 45203
A55: =ROW()-3 -> 52 | B55: 0176-57868667 | C55: 00001-62662032-5 | D55: 0061649340 | E55: 87027522 | F55: TM217 | H55: X | I55: 45415 | J55: 45234 | K55: 45200 | N55: O | O55: TM | P55: BMSH3 | U55: 45248 | V55: BMMSH3 | Z55: 265 | AA55: {=Vorlauf(Tabelle13[[#This Row],[Anbieter]])} -> 6 | AB55: =IFERROR(EDATE(Tabelle13[[#This Row],[Vertragsende]], -Tabelle13[[#This Row],[Vorlauf]]) + 1,"") -> 45234 | AC55: =IFERROR(EDATE(Tabelle13[[#This Row],[Vertragsende]], -Tabelle13[[#This Row],[Vorlauf]] - 1) + 1,"") -> 45203
A56: =ROW()-3 -> 53 | B56: 0176-71211976 | C56: 00001-62660003-8 | D56: 0061649340 | E56: 87027522 | F56: TM217 | H56: X | I56: 45415 | J56: 45234 | K56: 45200 | N56: O | O56: TM | P56: BMSH3 | U56: 45248 | V56: BMMSH3 | Z56: 265 | AA56: {=Vorlauf(Tabelle13[[#This Row],[Anbieter]])} -> 6 | AB56: =IFERROR(EDATE(Tabelle13[[#This Row],[Vertragsende]], -Tabelle13[[#This Row],[Vorlauf]]) + 1,"") -> 45234 | AC56: =IFERROR(EDATE(Tabelle13[[#This Row],[Vertragsende]], -Tabelle13[[#This Row],[Vorlauf]] - 1) + 1,"") -> 45203
A57: =ROW()-3 -> 54 | B57: 0151-18903607 | C57: 00001-76878897-1 | D57: 0061649340 | E57: 87027522 | F57: TM217 | H57: X | I57: 45430 | J57: 45249 | K57: 45200 | N57: O | O57: TM | P57: BMSH3 | U57: 45249 | V57: BMMSH3 | Z57: 265 | AA57: {=Vorlauf(Tabelle13[[#This Row],[Anbieter]])} -> 6 | AB57: =IFERROR(EDATE(Tabelle13[[#This Row],[Vertragsende]], -Tabelle13[[#This Row],[Vorlauf]]) + 1,"") -> 45249 | AC57: =IFERROR(EDATE(Tabelle13[[#This Row],[Vertragsende]], -Tabelle13[[#This Row],[Vorlauf]] - 1) + 1,"") -> 45218
A58: =ROW()-3 -> 55 | B58: 0151-16478328 | C58: 00001-76878849-2 | D58: 0061649340 | E58: 87027522 | F58: TM217 | H58: X | I58: 45430 | J58: 45249 | K58: 45200 | N58: O | O58: TM | P58: BMSH3 | U58: 45249 | V58: BMMSH3 | Z58: 265 | AA58: {=Vorlauf(Tabelle13[[#This Row],[Anbieter]])} -> 6 | AB58: =IFERROR(EDATE(Tabelle13[[#This Row],[Vertragsende]], -Tabelle13[[#This Row],[Vorlauf]]) + 1,"") -> 45249 | AC58: =IFERROR(EDATE(Tabelle13[[#This Row],[Vertragsende]], -Tabelle13[[#This Row],[Vorlauf]] - 1) + 1,"") -> 45218
A59: =ROW()-3 -> 56 | B59: 0151-43129622 | C59: 00001-80835358-8 | D59: 0061649340 | E59: 87027522 | F59: TM217 | H59: X | I59: 45455 | J59: 45273 | K59: 45231 | N59: O | O59: TM | P59: BMSH3 | U59: 45297 | V59: BMMSH3 | Z59: 265 | AA59: {=Vorlauf(Tabelle13[[#This Row],[Anbieter]])} -> 6 | AB59: =IFERROR(EDATE(Tabelle13[[#This Row],[Vertragsende]], -Tabelle13[[#This Row],[Vorlauf]]) + 1,"") -> 45273 | AC59: =IFERROR(EDATE(Tabelle13[[#This Row],[Vertragsende]], -Tabelle13[[#This Row],[Vorlauf]] - 1) + 1,"") -> 45243
A60: =ROW()-3 -> 57 | B60: 0151-43129209 | C60: 00001-80835355-4 | D60: 0061649340 | E60: 87027522 | F60: TM217 | H60: X | I60: 45455 | J60: 45273 | K60: 45231 | N60: O | O60: TM | P60: BMSH3 | U60: 45297 | V60: BMMSH3 | Z60: 265 | AA60: {=Vorlauf(Tabelle13[[#This Row],[Anbieter]])} -> 6 | AB60: =IFERROR(EDATE(Tabelle13[[#This Row],[Vertragsende]], -Tabelle13[[#This Row],[Vorlauf]]) + 1,"") -> 45273 | AC60: =IFERROR(EDATE(Tabelle13[[#This Row],[Vertragsende]], -Tabelle13[[#This Row],[Vorlauf]] - 1) + 1,"") -> 45243
A61: =ROW()-3 -> 58 | B61: 0151-43126823 | C61: 00001-80835352-1 | D61: 0061649340 | E61: 87027522 | F61: TM217 | H61: X | I61: 45455 | J61: 45273 | K61: 45231 | N61: O | O61: TM | P61: BMSH3 | U61: 45297 | V61: BMMSH3 | Z61: 265 | AA61: {=Vorlauf(Tabelle13[[#This Row],[Anbieter]])} -> 6 | AB61: =IFERROR(EDATE(Tabelle13[[#This Row],[Vertragsende]], -Tabelle13[[#This Row],[Vorlauf]]) + 1,"") -> 45273 | AC61: =IFERROR(EDATE(Tabelle13[[#This Row],[Vertragsende]], -Tabelle13[[#This Row],[Vorlauf]] - 1) + 1,"") -> 45243
A62: =ROW()-3 -> 59 | B62: 0151-43122884 | C62: 00001-80835349-7 | D62: 0061649340 | E62: 87027522 | F62: TM217 | H62: X | I62: 45455 | J62: 45273 | K62: 45231 | N62: O | O62: TM | P62: BMSH3 | U62: 45297 | V62: BMMSH3 | Z62: 265 | AA62: {=Vorlauf(Tabelle13[[#This Row],[Anbieter]])} -> 6 | AB62: =IFERROR(EDATE(Tabelle13[[#This Row],[Vertragsende]], -Tabelle13[[#This Row],[Vorlauf]]) + 1,"") -> 45273 | AC62: =IFERROR(EDATE(Tabelle13[[#This Row],[Vertragsende]], -Tabelle13[[#This Row],[Vorlauf]] - 1) + 1,"") -> 45243
A63: =ROW()-3 -> 60 | B63: 0151-43117054 | C63: 00001-80835346-3 | D63: 0061649340 | E63: 87027522 | F63: TM217 | H63: X | I63: 45455 | J63: 45273 | K63: 45231 | N63: O | O63: TM | P63: BMSH3 | U63: 45297 | V63: BMMSH3 | Z63: 265 | AA63: {=Vorlauf(Tabelle13[[#This Row],[Anbieter]])} -> 6 | AB63: =IFERROR(EDATE(Tabelle13[[#This Row],[Vertragsende]], -Tabelle13[[#This Row],[Vorlauf]]) + 1,"") -> 45273 | AC63: =IFERROR(EDATE(Tabelle13[[#This Row],[Vertragsende]], -Tabelle13[[#This Row],[Vorlauf]] - 1) + 1,"") -> 45243
A64: =ROW()-3 -> 61 | B64: 0151-28835002 | C64: 00001-80835343-0 | D64: 0061649340 | E64: 87027522 | F64: TM217 | H64: X | I64: 45455 | J64: 45273 | K64: 45231 | N64: O | O64: TM | P64: BMSH3 | U64: 45297 | V64: BMMSH3 | W64: Samsung Galaxy A34 5G 128GB Awesome Graphit EE EU | Z64: 265 | AA64: {=Vorlauf(Tabelle13[[#This Row],[Anbieter]])} -> 6 | AB64: =IFERROR(EDATE(Tabelle13[[#This Row],[Vertragsende]], -Tabelle13[[#This Row],[Vorlauf]]) + 1,"") -> 45273 | AC64: =IFERROR(EDATE(Tabelle13[[#This Row],[Vertragsende]], -Tabelle13[[#This Row],[Vorlauf]] - 1) + 1,"") -> 45243
A65: =ROW()-3 -> 62 | B65: 0151-16726447 | C65: 00001-64459175-5 | D65: 0061649340 | E65: 87027522 | F65: TM217 | I65: 45468 | J65: 45286 | K65: 45231 | N65: O | O65: TM | P65: BMDSH | U65: 45297 | V65: BMDSH | Z65: 165 | AA65: {=Vorlauf(Tabelle13[[#This Row],[Anbieter]])} -> 6 | AB65: =IFERROR(EDATE(Tabelle13[[#This Row],[Vertragsende]], -Tabelle13[[#This Row],[Vorlauf]]) + 1,"") -> 45286 | AC65: =IFERROR(EDATE(Tabelle13[[#This Row],[Vertragsende]], -Tabelle13[[#This Row],[Vorlauf]] - 1) + 1,"") -> 45256
A66: =ROW()-3 -> 63 | B66: 0151-18954341 | C66: 00001-64459176-3 | D66: 0061649340 | E66: 87027522 | F66: TM217 | I66: 45468 | J66: 45286 | K66: 45231 | N66: O | O66: TM | P66: BMDSH | U66: 45297 | V66: BMDSH | Z66: 165 | AA66: {=Vorlauf(Tabelle13[[#This Row],[Anbieter]])} -> 6 | AB66: =IFERROR(EDATE(Tabelle13[[#This Row],[Vertragsende]], -Tabelle13[[#This Row],[Vorlauf]]) + 1,"") -> 45286 | AC66: =IFERROR(EDATE(Tabelle13[[#This Row],[Vertragsende]], -Tabelle13[[#This Row],[Vorlauf]] - 1) + 1,"") -> 45256
A67: =ROW()-3 -> 64 | B67: 0151-18956409 | C67: 00001-64459177-1 | D67: 0061649340 | E67: 87027522 | F67: TM217 | I67: 45468 | J67: 45286 | K67: 45231 | N67: O | O67: TM | P67: BMDSH | U67: 45297 | V67: BMDSH | Z67: 165 | AA67: {=Vorlauf(Tabelle13[[#This Row],[Anbieter]])} -> 6 | AB67: =IFERROR(EDATE(Tabelle13[[#This Row],[Vertragsende]], -Tabelle13[[#This Row],[Vorlauf]]) + 1,"") -> 45286 | AC67: =IFERROR(EDATE(Tabelle13[[#This Row],[Vertragsende]], -Tabelle13[[#This Row],[Vorlauf]] - 1) + 1,"") -> 45256
A68: =ROW()-3 -> 65 | B68: 0151-18991257 | C68: 00001-64459187-9 | D68: 0061649340 | E68: 87027522 | F68: TM217 | I68: 45468 | J68: 45286 | K68: 45231 | N68: O | O68: TM | P68: BMDSH | U68: 45297 | V68: BMDSH | Z68: 165 | AA68: {=Vorlauf(Tabelle13[[#This Row],[Anbieter]])} -> 6 | AB68: =IFERROR(EDATE(Tabelle13[[#This Row],[Vertragsende]], -Tabelle13[[#This Row],[Vorlauf]]) + 1,"") -> 45286 | AC68: =IFERROR(EDATE(Tabelle13[[#This Row],[Vertragsende]], -Tabelle13[[#This Row],[Vorlauf]] - 1) + 1,"") -> 45256
A69: =ROW()-3 -> 66 | B69: 0151-18992815 | C69: 00001-64459179-7 | D69: 0061649340 | E69: 87027522 | F69: TM217 | I69: 45468 | J69: 45286 | K69: 45231 | N69: O | O69: TM | P69: BMDSH | U69: 45297 | V69: BMDSH | Z69: 165 | AA69: {=Vorlauf(Tabelle13[[#This Row],[Anbieter]])} -> 6 | AB69: =IFERROR(EDATE(Tabelle13[[#This Row],[Vertragsende]], -Tabelle13[[#This Row],[Vorlauf]]) + 1,"") -> 45286 | AC69: =IFERROR(EDATE(Tabelle13[[#This Row],[Vertragsende]], -Tabelle13[[#This Row],[Vorlauf]] - 1) + 1,"") -> 45256
...

Sheet 3
A1: Verträge von | C1: {=Fullname(Kunde!$B$4,Kunde!$B$5) & ", " & Kunde!$B$7} -> Friedrich von Lien AG, 27404 Zeven
A2: Vertrag | O2: Aktuell | U2: Vertragseingabe
A3: Nr. | B3: Rufnummer | C3: SIM-Nr | D3: Kundenkonto | E3: Kunden-Nr | F3: RV | G3: Künd. | H3: Multi Ultra | I3: Vertragsende | J3: VVL | K3: WV | L3: Nutzer | M3: Kost | N3: RG Form | O3: Anbieter | P3: Tarif aktuell | Q3: Option 1 | R3: Option 2 | S3: Option 3 | T3: Option 4 | U3: Aktiviert | V3: Tarif neu | W3: Handy | X3: Gutschrift | Y3: RG-Nummer | Z3: Provision | AA3: Vorlauf | AB3: Test VVL | AC3: Test WV
A4: =ROW()-3 -> 1 | B4: 0160-97569583 | C4: 00001-78833193-5 | D4: 0065542707 | E4: 87027522 | F4: TM327 | G4: X | H4: X | I4: 46007 | J4: 45825 | K4: 45778 | N4: O | O4: TM | P4: BMMSH3 | U4: 45900 | V4: BMMS5 | Z4: 290 | AA4: {=Vorlauf(Tabelle134[[#This Row],[Anbieter]])} -> 6 | AB4: =IFERROR(EDATE(Tabelle134[[#This Row],[Vertragsende]], -Tabelle134[[#This Row],[Vorlauf]]) + 1, "") -> 45825 | AC4: =IFERROR(EDATE(Tabelle134[[#This Row],[Vertragsende]], -Tabelle134[[#This Row],[Vorlauf]] - 1) + 1, "") -> 45794
A5: =ROW()-3 -> 2 | B5: 0160-97569133 | C5: 00001-78833192-7 | D5: 0065542707 | E5: 87027522 | F5: TM327 | G5: X | H5: X | I5: 46007 | J5: 45825 | K5: 45778 | N5: O | O5: TM | P5: BMMSH3 | U5: 45900 | V5: BMMS5 | Z5: 290 | AA5: {=Vorlauf(Tabelle134[[#This Row],[Anbieter]])} -> 6 | AB5: =IFERROR(EDATE(Tabelle134[[#This Row],[Vertragsende]], -Tabelle134[[#This Row],[Vorlauf]]) + 1, "") -> 45825 | AC5: =IFERROR(EDATE(Tabelle134[[#This Row],[Vertragsende]], -Tabelle134[[#This Row],[Vorlauf]] - 1) + 1, "") -> 45794
A6: =ROW()-3 -> 3 | B6: 0160-97236581 | C6: 00001-78833191-9 | D6: 0065542707 | E6: 87027522 | F6: TM327 | G6: X | I6: 46007 | J6: 45825 | K6: 45778 | N6: O | O6: TM | P6: BMSH3 | U6: 45900 | V6: BMMS5 | Z6: 380 | AA6: {=Vorlauf(Tabelle134[[#This Row],[Anbieter]])} -> 6 | AB6: =IFERROR(EDATE(Tabelle134[[#This Row],[Vertragsende]], -Tabelle134[[#This Row],[Vorlauf]]) + 1, "") -> 45825 | AC6: =IFERROR(EDATE(Tabelle134[[#This Row],[Vertragsende]], -Tabelle134[[#This Row],[Vorlauf]] - 1) + 1, "") -> 45794
A7: =ROW()-3 -> 4 | B7: 0151-41385527 | C7: 00001-81614931-7 | D7: 0065542707 | E7: 87027522 | F7: TM327 | G7: X | H7: X | I7: 46050 | J7: 45867 | K7: 45809 | N7: O | O7: TM | P7: BMSH3 | U7: 45900 | V7: BMMS5 | Z7: 380 | AA7: {=Vorlauf(Tabelle134[[#This Row],[Anbieter]])} -> 6 | AB7: =IFERROR(EDATE(Tabelle134[[#This Row],[Vertragsende]], -Tabelle134[[#This Row],[Vorlauf]]) + 1, "") -> 45867 | AC7: =IFERROR(EDATE(Tabelle134[[#This Row],[Vertragsende]], -Tabelle134[[#This Row],[Vorlauf]] - 1) + 1, "") -> 45837
A8: =ROW()-3 -> 5 | B8: 0176-44424101 | C8: 00001-84783936-5 | D8: 0065542707 | E8: 87027522 | F8: TM327 | G8: X | H8: X | I8: 46080 | J8: 45897 | K8: 45839 | N8: O | O8: TM | P8: BMMH3 | Q8: CF1+ | U8: 45900 | V8: BMLS5 | Z8: 500 | AA8: {=Vorlauf(Tabelle134[[#This Row],[Anbieter]])} -> 6 | AB8: =IFERROR(EDATE(Tabelle134[[#This Row],[Vertragsende]], -Tabelle134[[#This Row],[Vorlauf]]) + 1, "") -> 45897 | AC8: =IFERROR(EDATE(Tabelle134[[#This Row],[Vertragsende]], -Tabelle134[[#This Row],[Vorlauf]] - 1) + 1, "") -> 45866
A9: =ROW()-3 -> 6 | B9: 0171-2120735 | C9: 00001-77887291-4 | D9: 0065542707 | E9: 87027522 | F9: TM327 | G9: X | H9: X | I9: 46124 | J9: 46094 | K9: 46023 | N9: O | O9: TM | P9: BMMSH3 | U9: 45953 | V9: BMLS5 | Z9: 500 | AA9: {=Vorlauf(Tabelle134[[#This Row],[Anbieter]])} -> 6 | AB9: =IFERROR(EDATE(Tabelle134[[#This Row],[Vertragsende]], -Tabelle134[[#This Row],[Vorlauf]]) + 1, "") -> 45943 | AC9: =IFERROR(EDATE(Tabelle134[[#This Row],[Vertragsende]], -Tabelle134[[#This Row],[Vorlauf]] - 1) + 1, "") -> 45913
A10: =ROW()-3 -> 7 | B10: 0175-4549654 | C10: 00001-98903352-0 | D10: 0065542707 | E10: 87027522 | F10: TM327 | G10: X | I10: 46126 | J10: 46096 | K10: 46023 | N10: O | O10: TM | P10: BMDSH | U10: 45953 | V10: BMDSH | Z10: 165 | AA10: {=Vorlauf(Tabelle134[[#This Row],[Anbieter]])} -> 6 | AB10: =IFERROR(EDATE(Tabelle134[[#This Row],[Vertragsende]], -Tabelle134[[#This Row],[Vorlauf]]) + 1, "") -> 45945 | AC10: =IFERROR(EDATE(Tabelle134[[#This Row],[Vertragsende]], -Tabelle134[[#This Row],[Vorlauf]] - 1) + 1, "") -> 45915
A11: =ROW()-3 -> 8 | B11: 0175-6013246 | C11: 00001-62625118-8 | D11: 0065542707 | E11: 87027522 | F11: TM327 | G11: X | I11: 46126 | J11: 46096 | K11: 46023 | N11: O | O11: TM | P11: BMDSH | U11: 45953 | V11: BMDSH | Z11: 165 | AA11: {=Vorlauf(Tabelle134[[#This Row],[Anbieter]])} -> 6 | AB11: =IFERROR(EDATE(Tabelle134[[#This Row],[Vertragsende]], -Tabelle134[[#This Row],[Vorlauf]]) + 1, "") -> 45945 | AC11: =IFERROR(EDATE(Tabelle134[[#This Row],[Vertragsende]], -Tabelle134[[#This Row],[Vorlauf]] - 1) + 1, "") -> 45915
A12: =ROW()-3 -> 9 | B12: 0175-6016444 | C12: 00001-61558918-4 | D12: 0065542707 | E12: 87027522 | F12: TM327 | G12: X | I12: 46126 | J12: 46096 | K12: 46023 | N12: O | O12: TM | P12: BMDSH | U12: 45953 | V12: BMDSH | Z12: 165 | AA12: {=Vorlauf(Tabelle134[[#This Row],[Anbieter]])} -> 6 | AB12: =IFERROR(EDATE(Tabelle134[[#This Row],[Vertragsende]], -Tabelle134[[#This Row],[Vorlauf]]) + 1, "") -> 45945 | AC12: =IFERROR(EDATE(Tabelle134[[#This Row],[Vertragsende]], -Tabelle134[[#This Row],[Vorlauf]] - 1) + 1, "") -> 45915
A13: =ROW()-3 -> 10 | B13: 0175-6028099 | C13: 00001-61558919-2 | D13: 0065542707 | E13: 87027522 | F13: TM327 | G13: X | I13: 46126 | J13: 46096 | K13: 46023 | N13: O | O13: TM | P13: BMDSH | U13: 45953 | V13: BMDSH | Z13: 165 | AA13: {=Vorlauf(Tabelle134[[#This Row],[Anbieter]])} -> 6 | AB13: =IFERROR(EDATE(Tabelle134[[#This Row],[Vertragsende]], -Tabelle134[[#This Row],[Vorlauf]]) + 1, "") -> 45945 | AC13: =IFERROR(EDATE(Tabelle134[[#This Row],[Vertragsende]], -Tabelle134[[#This Row],[Vorlauf]] - 1) + 1, "") -> 45915
A14: =ROW()-3 -> 11 | B14: 0175-6030029 | C14: 00001-63583428-9 | D14: 0065542707 | E14: 87027522 | F14: TM327 | G14: X | I14: 46126 | J14: 46096 | K14: 46023 | N14: O | O14: TM | P14: BMDSH | U14: 45953 | V14: BMDSH | Z14: 165 | AA14: {=Vorlauf(Tabelle134[[#This Row],[Anbieter]])} -> 6 | AB14: =IFERROR(EDATE(Tabelle134[[#This Row],[Vertragsende]], -Tabelle134[[#This Row],[Vorlauf]]) + 1, "") -> 45945 | AC14: =IFERROR(EDATE(Tabelle134[[#This Row],[Vertragsende]], -Tabelle134[[#This Row],[Vorlauf]] - 1) + 1, "") -> 45915
A15: =ROW()-3 -> 12 | B15: 0175-6030705 | C15: 00001-63583429-7 | D15: 0065542707 | E15: 87027522 | F15: TM327 | G15: X | I15: 46126 | J15: 46096 | K15: 46023 | N15: O | O15: TM | P15: BMDSH | U15: 45953 | V15: BMDSH | Z15: 165 | AA15: {=Vorlauf(Tabelle134[[#This Row],[Anbieter]])} -> 6 | AB15: =IFERROR(EDATE(Tabelle134[[#This Row],[Vertragsende]], -Tabelle134[[#This Row],[Vorlauf]]) + 1, "") -> 45945 | AC15: =IFERROR(EDATE(Tabelle134[[#This Row],[Vertragsende]], -Tabelle134[[#This Row],[Vorlauf]] - 1) + 1, "") -> 45915
A16: =ROW()-3 -> 13 | B16: 0175-6036922 | C16: 00001-63583430-5 | D16: 0065542707 | E16: 87027522 | F16: TM327 | G16: X | I16: 46126 | J16: 46096 | K16: 46023 | N16: O | O16: TM | P16: BMDSH | U16: 45953 | V16: BMDSH | Z16: 165 | AA16: {=Vorlauf(Tabelle134[[#This Row],[Anbieter]])} -> 6 | AB16: =IFERROR(EDATE(Tabelle134[[#This Row],[Vertragsende]], -Tabelle134[[#This Row],[Vorlauf]]) + 1, "") -> 45945 | AC16: =IFERROR(EDATE(Tabelle134[[#This Row],[Vertragsende]], -Tabelle134[[#This Row],[Vorlauf]] - 1) + 1, "") -> 45915
A17: =ROW()-3 -> 14 | B17: 0175-6041441 | C17: 00001-63583431-3 | D17: 0065542707 | E17: 87027522 | F17: TM327 | G17: X | I17: 46126 | J17: 46096 | K17: 46023 | N17: O | O17: TM | P17: BMDSH | U17: 45953 | V17: BMDSH | Z17: 165 | AA17: {=Vorlauf(Tabelle134[[#This Row],[Anbieter]])} -> 6 | AB17: =IFERROR(EDATE(Tabelle134[[#This Row],[Vertragsende]], -Tabelle134[[#This Row],[Vorlauf]]) + 1, "") -> 45945 | AC17: =IFERROR(EDATE(Tabelle134[[#This Row],[Vertragsende]], -Tabelle134[[#This Row],[Vorlauf]] - 1) + 1, "") -> 45915
A18: =ROW()-3 -> 15 | B18: 0175-6044274 | C18: 00001-63583432-1 | D18: 0065542707 | E18: 87027522 | F18: TM327 | G18: X | I18: 46126 | J18: 46096 | K18: 46023 | N18: O | O18: TM | P18: BMDSH | U18: 45953 | V18: BMDSH | Z18: 165 | AA18: {=Vorlauf(Tabelle134[[#This Row],[Anbieter]])} -> 6 | AB18: =IFERROR(EDATE(Tabelle134[[#This Row],[Vertragsende]], -Tabelle134[[#This Row],[Vorlauf]]) + 1, "") -> 45945 | AC18: =IFERROR(EDATE(Tabelle134[[#This Row],[Vertragsende]], -Tabelle134[[#This Row],[Vorlauf]] - 1) + 1, "") -> 45915
A19: =ROW()-3 -> 16 | B19: 0175-6050220 | C19: 00001-63583433-9 | D19: 0065542707 | E19: 87027522 | F19: TM327 | G19: X | I19: 46126 | J19: 46096 | K19: 46023 | N19: O | O19: TM | P19: BMDSH | U19: 45953 | V19: BMDSH | Z19: 165 | AA19: {=Vorlauf(Tabelle134[[#This Row],[Anbieter]])} -> 6 | AB19: =IFERROR(EDATE(Tabelle134[[#This Row],[Vertragsende]], -Tabelle134[[#This Row],[Vorlauf]]) + 1, "") -> 45945 | AC19: =IFERROR(EDATE(Tabelle134[[#This Row],[Vertragsende]], -Tabelle134[[#This Row],[Vorlauf]] - 1) + 1, "") -> 45915
A20: =ROW()-3 -> 17 | B20: 0175-6059733 | C20: 00001-63583434-7 | D20: 0065542707 | E20: 87027522 | F20: TM327 | G20: X | I20: 46126 | J20: 46096 | K20: 46023 | N20: O | O20: TM | P20: BMDSH | U20: 45953 | V20: BMDSH | Z20: 165 | AA20: {=Vorlauf(Tabelle134[[#This Row],[Anbieter]])} -> 6 | AB20: =IFERROR(EDATE(Tabelle134[[#This Row],[Vertragsende]], -Tabelle134[[#This Row],[Vorlauf]]) + 1, "") -> 45945 | AC20: =IFERROR(EDATE(Tabelle134[[#This Row],[Vertragsende]], -Tabelle134[[#This Row],[Vorlauf]] - 1) + 1, "") -> 45915
A21: =ROW()-3 -> 18 | B21: 0175-6061688 | C21: 00001-63583435-4 | D21: 0065542707 | E21: 87027522 | F21: TM327 | G21: X | I21: 46126 | J21: 46096 | K21: 46023 | N21: O | O21: TM | P21: BMDSH | U21: 45953 | V21: BMDSH | Z21: 165 | AA21: {=Vorlauf(Tabelle134[[#This Row],[Anbieter]])} -> 6 | AB21: =IFERROR(EDATE(Tabelle134[[#This Row],[Vertragsende]], -Tabelle134[[#This Row],[Vorlauf]]) + 1, "") -> 45945 | AC21: =IFERROR(EDATE(Tabelle134[[#This Row],[Vertragsende]], -Tabelle134[[#This Row],[Vorlauf]] - 1) + 1, "") -> 45915
... A51: =ROW()-3 -> 48 | B51: 0175-9012200 | C51: 00001-63583465-1 | D51: 0065542707 | E51: 87027522 | F51: TM327 | G51: X | I51: 46126 | J51: 46096 | K51: 46023 | N51: O | O51: TM | P51: BMDSH | U51: 45953 | V51: BMDSH | Z51: 165 | AA51: {=Vorlauf(Tabelle134[[#This Row],[Anbieter]])} -> 6 | AB51: =IFERROR(EDATE(Tabelle134[[#This Row],[Vertragsende]], -Tabelle134[[#This Row],[Vorlauf]]) + 1, "") -> 45945 | AC51: =IFERROR(EDATE(Tabelle134[[#This Row],[Vertragsende]], -Tabelle134[[#This Row],[Vorlauf]] - 1) + 1, "") -> 45915
A52: =ROW()-3 -> 49 | B52: 0176-34316593 | C52: 00001-62660116-8 | D52: 0065542707 | E52: 87027522 | F52: TM327 | G52: X | H52: X | I52: 46145 | J52: 46116 | K52: 46054 | N52: O | O52: TM | P52: BMMSH3 | AA52: {=Vorlauf(Tabelle134[[#This Row],[Anbieter]])} -> 6 | AB52: =IFERROR(EDATE(Tabelle134[[#This Row],[Vertragsende]], -Tabelle134[[#This Row],[Vorlauf]]) + 1, "") -> 45965 | AC52: =IFERROR(EDATE(Tabelle134[[#This Row],[Vertragsende]], -Tabelle134[[#This Row],[Vorlauf]] - 1) + 1, "") -> 45934
A53: =ROW()-3 -> 50 | B53: 0176-34319589 | C53: 00001-97802699-8 | D53: 0065542707 | E53: 87027522 | F53: TM327 | G53: X | H53: X | I53: 46145 | J53: 46116 | K53: 46054 | N53: O | O53: TM | P53: BMMSH3 | AA53: {=Vorlauf(Tabelle134[[#This Row],[Anbieter]])} -> 6 | AB53: =IFERROR(EDATE(Tabelle134[[#This Row],[Vertragsende]], -Tabelle134[[#This Row],[Vorlauf]]) + 1, "") -> 45965 | AC53: =IFERROR(EDATE(Tabelle134[[#This Row],[Vertragsende]], -Tabelle134[[#This Row],[Vorlauf]] - 1) + 1, "") -> 45934
A54: =ROW()-3 -> 51 | B54: 0176-34372893 | C54: 00001-62662120-8 | D54: 0065542707 | E54: 87027522 | F54: TM327 | G54: X | H54: X | I54: 46145 | J54: 46116 | K54: 46054 | N54: O | O54: TM | P54: BMMSH3 | AA54: {=Vorlauf(Tabelle134[[#This Row],[Anbieter]])} -> 6 | AB54: =IFERROR(EDATE(Tabelle134[[#This Row],[Vertragsende]], -Tabelle134[[#This Row],[Vorlauf]]) + 1, "") -> 45965 | AC54: =IFERROR(EDATE(Tabelle134[[#This Row],[Vertragsende]], -Tabelle134[[#This Row],[Vorlauf]] - 1) + 1, "") -> 45934
A55: =ROW()-3 -> 52 | B55: 0176-45989519 | C55: 00001-62662477-2 | D55: 0065542707 | E55: 87027522 | F55: TM327 | G55: X | H55: X | I55: 46145 | J55: 46116 | K55: 46054 | N55: O | O55: TM | P55: BMMSH3 | AA55: {=Vorlauf(Tabelle134[[#This Row],[Anbieter]])} -> 6 | AB55: =IFERROR(EDATE(Tabelle134[[#This Row],[Vertragsende]], -Tabelle134[[#This Row],[Vorlauf]]) + 1, "") -> 45965 | AC55: =IFERROR(EDATE(Tabelle134[[#This Row],[Vertragsende]], -Tabelle134[[#This Row],[Vorlauf]] - 1) + 1, "") -> 45934
A56: =ROW()-3 -> 53 | B56: 0176-45989521 | C56: 00001-62662475-6 | D56: 0065542707 | E56: 87027522 | F56: TM327 | G56: X | H56: X | I56: 46145 | J56: 46116 | K56: 46054 | N56: O | O56: TM | P56: BMMSH3 | AA56: {=Vorlauf(Tabelle134[[#This Row],[Anbieter]])} -> 6 | AB56: =IFERROR(EDATE(Tabelle134[[#This Row],[Vertragsende]], -Tabelle134[[#This Row],[Vorlauf]]) + 1, "") -> 45965 | AC56: =IFERROR(EDATE(Tabelle134[[#This Row],[Vertragsende]], -Tabelle134[[#This Row],[Vorlauf]] - 1) + 1, "") -> 45934
A57: =ROW()-3 -> 54 | B57: 0176-45989542 | C57: 00001-62662476-4 | D57: 0065542707 | E57: 87027522 | F57: TM327 | G57: X | H57: X | I57: 46145 | J57: 46116 | K57: 46054 | N57: O | O57: TM | P57: BMMSH3 | AA57: {=Vorlauf(Tabelle134[[#This Row],[Anbieter]])} -> 6 | AB57: =IFERROR(EDATE(Tabelle134[[#This Row],[Vertragsende]], -Tabelle134[[#This Row],[Vorlauf]]) + 1, "") -> 45965 | AC57: =IFERROR(EDATE(Tabelle134[[#This Row],[Vertragsende]], -Tabelle134[[#This Row],[Vorlauf]] - 1) + 1, "") -> 45934
A58: =ROW()-3 -> 55 | B58: 0176-47117018 | C58: 00001-63593362-8 | D58: 0065542707 | E58: 87027522 | F58: TM327 | G58: X | H58: X | I58: 46145 | J58: 46116 | K58: 46054 | N58: O | O58: TM | P58: BMMSH3 | Q58: CF1+ | AA58: {=Vorlauf(Tabelle134[[#This Row],[Anbieter]])} -> 6 | AB58: =IFERROR(EDATE(Tabelle134[[#This Row],[Vertragsende]], -Tabelle134[[#This Row],[Vorlauf]]) + 1, "") -> 45965 | AC58: =IFERROR(EDATE(Tabelle134[[#This Row],[Vertragsende]], -Tabelle134[[#This Row],[Vorlauf]] - 1) + 1, "") -> 45934
A59: =ROW()-3 -> 56 | B59: 0176-56788683 | C59: 00001-63593442-8 | D59: 0065542707 | E59: 87027522 | F59: TM327 | G59: X | H59: X | I59: 46145 | J59: 46116 | K59: 46054 | N59: O | O59: TM | P59: BMSH3 | AA59: {=Vorlauf(Tabelle134[[#This Row],[Anbieter]])} -> 6 | AB59: =IFERROR(EDATE(Tabelle134[[#This Row],[Vertragsende]], -Tabelle134[[#This Row],[Vorlauf]]) + 1, "") -> 45965 | AC59: =IFERROR(EDATE(Tabelle134[[#This Row],[Vertragsende]], -Tabelle134[[#This Row],[Vorlauf]] - 1) + 1, "") -> 45934
A60: =ROW()-3 -> 57 | B60: 0176-57868667 | C60: 00002-00118676-7 | D60: 0065542707 | E60: 87027522 | F60: TM327 | G60: X | H60: X | I60: 46145 | J60: 46116 | K60: 46054 | N60: O | O60: TM | P60: BMMSH3 | AA60: {=Vorlauf(Tabelle134[[#This Row],[Anbieter]])} -> 6 | AB60: =IFERROR(EDATE(Tabelle134[[#This Row],[Vertragsende]], -Tabelle134[[#This Row],[Vorlauf]]) + 1, "") -> 45965 | AC60: =IFERROR(EDATE(Tabelle134[[#This Row],[Vertragsende]], -Tabelle134[[#This Row],[Vorlauf]] - 1) + 1, "") -> 45934
A61: =ROW()-3 -> 58 | B61: 0176-71211976 | C61: 00001-62660003-8 | D61: 0065542707 | E61: 87027522 | F61: TM327 | G61: X | H61: X | I61: 46145 | J61: 46116 | K61: 46054 | N61: O | O61: TM | P61: BMMSH3 | AA61: {=Vorlauf(Tabelle134[[#This Row],[Anbieter]])} -> 6 | AB61: =IFERROR(EDATE(Tabelle134[[#This Row],[Vertragsende]], -Tabelle134[[#This Row],[Vorlauf]]) + 1, "") -> 45965 | AC61: =IFERROR(EDATE(Tabelle134[[#This Row],[Vertragsende]], -Tabelle134[[#This Row],[Vorlauf]] - 1) + 1, "") -> 45934
A62: =ROW()-3 -> 59 | B62: 0151-18903607 | C62: 00002-10026603-1 | D62: 0065542707 | E62: 87027522 | F62: TM327 | G62: X | H62: X | I62: 46160 | J62: 46131 | K62: 46054 | N62: O | O62: TM | P62: BMMSH3 | AA62: {=Vorlauf(Tabelle134[[#This Row],[Anbieter]])} -> 6 | AB62: =IFERROR(EDATE(Tabelle134[[#This Row],[Vertragsende]], -Tabelle134[[#This Row],[Vorlauf]]) + 1, "") -> 45980 | AC62: =IFERROR(EDATE(Tabelle134[[#This Row],[Vertragsende]], -Tabelle134[[#This Row],[Vorlauf]] - 1) + 1, "") -> 45949
A63: =ROW()-3 -> 60 | B63: 0151-16478328 | C63: 00001-76878849-2 | D63: 0065542707 | E63: 87027522 | F63: TM327 | G63: X | H63: X | I63: 46160 | J63: 46131 | K63: 46054 | N63: O | O63: TM | P63: BMMSH3 | AA63: {=Vorlauf(Tabelle134[[#This Row],[Anbieter]])} -> 6 | AB63: =IFERROR(EDATE(Tabelle134[[#This Row],[Vertragsende]], -Tabelle134[[#This Row],[Vorlauf]]) + 1, "") -> 45980 | AC63: =IFERROR(EDATE(Tabelle134[[#This Row],[Vertragsende]], -Tabelle134[[#This Row],[Vorlauf]] - 1) + 1, "") -> 45949
A64: =ROW()-3 -> 61 | B64: 0151-66464038 | C64: 00001-96963933-8 | D64: 0065542707 | E64: 87027522 | F64: TM327 | G64: X | I64: 46171 | J64: 46142 | K64: 46054 | N64: O | O64: TM | P64: BMMH3 | Q64: CF1+ | AA64: {=Vorlauf(Tabelle134[[#This Row],[Anbieter]])} -> 6 | AB64: =IFERROR(EDATE(Tabelle134[[#This Row],[Vertragsende]], -Tabelle134[[#This Row],[Vorlauf]]) + 1, "") -> 45991 | AC64: =IFERROR(EDATE(Tabelle134[[#This Row],[Vertragsende]], -Tabelle134[[#This Row],[Vorlauf]] - 1) + 1, "") -> 45960
A65: =ROW()-3 -> 62 | B65: 0151-43129622 | C65: 00001-80835358-8 | D65: 0065542707 | E65: 87027522 | F65: TM327 | G65: X | H65: X | I65: 46185 | J65: 46155 | K65: 46082 | N65: O | O65: TM | P65: BMMSH3 | AA65: {=Vorlauf(Tabelle134[[#This Row],[Anbieter]])} -> 6 | AB65: =IFERROR(EDATE(Tabelle134[[#This Row],[Vertragsende]], -Tabelle134[[#This Row],[Vorlauf]]) + 1, "") -> 46004 | AC65: =IFERROR(EDATE(Tabelle134[[#This Row],[Vertragsende]], -Tabelle134[[#This Row],[Vorlauf]] - 1) + 1, "") -> 45974
A66: =ROW()-3 -> 63 | B66: 0151-43129209 | C66: 00001-80835355-4 | D66: 0065542707 | E66: 87027522 | F66: TM327 | G66: X | H66: X | I66: 46185 | J66: 46155 | K66: 46082 | N66: O | O66: TM | P66: BMMSH3 | AA66: {=Vorlauf(Tabelle134[[#This Row],[Anbieter]])} -> 6 | AB66: =IFERROR(EDATE(Tabelle134[[#This Row],[Vertragsende]], -Tabelle134[[#This Row],[Vorlauf]]) + 1, "") -> 46004 | AC66: =IFERROR(EDATE(Tabelle134[[#This Row],[Vertragsende]], -Tabelle134[[#This Row],[Vorlauf]] - 1) + 1, "") -> 45974
